Workbook

Sheet Template
A1: HYBRID OR INSTALLER PLUMBER COMMISSION TEMPLATE
B2: WEEKLY COMMISSION | F2: WEEK ENDING
K3: PHOTOS | N3: QUOTE | Q3: INVOICE
B4: BOOKED JOBS | C4: =C5+C6 -> 0 | E4: WEEKLY TARGET | K4: BEFORE | L4: AFTER | M4: RECEIPT | N4: DESCRIPTION | O4: SIGNED | P4: EMAILED | Q4: DESCRIPTION | R4: SIGNED | S4: EMAILED | T4: 5 Star Review
B5: SUCCESSFUL | C5: =P12 -> 0 | E5: Tier 1 | F5: 0.05 | J5: TAKEN | K5: =K46 -> 0 | L5: =L46 -> 0 | M5: =M46 -> 0 | N5: =N46 -> 0 | O5: =O46 -> 0 | P5: =P46 -> 0 | Q5: =Q46 -> 0 | R5: =R46 -> 0 | S5: =S46 -> 0 | T5: =T143 -> 0
B6: UNSUCCESSFUL | C6: =P13 -> 0 | J6: % | K6: =K46/K45 -> #DIV/0! | L6: =L46/L45 -> #DIV/0! | M6: =M46/M45 -> #DIV/0! | N6: =N46/N45 -> #DIV/0! | O6: =O46/O45 -> #DIV/0! | P6: =P46/P45 -> #DIV/0! | Q6: =Q46/Q45 -> #DIV/0! | R6: =R46/R45 -> #DIV/0! | S6: =S46/S45 -> #DIV/0! | U6: M8 Notes
B7: SUCESSFUL (%) | C7: =P14 -> #DIV/0!
F8: ACTUAL | G8: POTENTIAL | H8: Exc. SUPER
B9: AVERAGE SALE | C9: =P15 -> #DIV/0! | E9: NET PROFIT | F9: =P11 -> 0 | G9: =I45+I79+I101 -> 0 | K9: DAILY NET PROFIT | R9: WEEKDAY | S9: WEEKEND
E10: UNLOCKED | F10: =F5 -> 0.05 | K10: MON | L10: TUE | M10: WED | N10: THU | O10: FRI | P10: Total | Q10: SAT | R10: Awaiting Payment | S10: Awaiting Payment
E11: COMMISSION - PAY OUT | F11: =F9*F10 -> 0 | G11: $- | H11: =F11/1.12 -> 0 | P11: =SUM(K11:O11) -> 0 | Q11: 0 | R11: =I79+I101 -> 0 | S11: =I90+I112 -> 0
E12: EMERGENCY | F12: =Q11 -> 0 | G12: $- | J12: Successful | P12: =SUM(K12:O12) -> 0
E13: EMERGENCY - PAY OUT | F13: =F12*0.25 -> 0 | G13: $- | H13: =F13/1.12 -> 0 | J13: Unsuccessful | P13: =SUM(K13:O13) -> 0
E14: PREV. WEEK | G14: $- | J14: Success rate | K14: =K12/(K12+K13) -> #DIV/0! | L14: =L12/(L12+L13) -> #DIV/0! | M14: =M12/(M12+M13) -> #DIV/0! | N14: =N12/(N12+N13) -> #DIV/0! | O14: =O12/(O12+O13) -> #DIV/0! | P14: =P12/(P12+P13) -> #DIV/0! | Q14: =Q12/(Q12+Q13) -> #DIV/0!
E15: PREV. WEEK - PAY OUT | F15: =F14*0.05 -> 0 | G15: $- | H15: =F15/1.12 -> 0 | J15: Avg sale | K15: =K11/K12 -> #DIV/0! | L15: =L11/L12 -> #DIV/0! | M15: =M11/M12 -> #DIV/0! | N15: =N11/N12 -> #DIV/0! | O15: =O11/O12 -> #DIV/0! | P15: =P11/P12 -> #DIV/0! | Q15: =Q11/Q12 -> #DIV/0!
E16: 5 Star Review | H16: =F16/1.12 -> 0
E17: 5 Star Notes | F17: =T6 -> 0 | K17: Managment Summary - SALES ONLY - COLUMN F | R17: WEEKDAY | S17: WEEKEND
K18: MON | L18: TUE | M18: WED | N18: THU | O18: FRI | P18: Total | Q18: SAT | R18: Awaiting Payment | S18: Awaiting Payment
Q19: 0 | R19: =F79+F101 -> 0 | S19: =F90+F112 -> 0
J20: Successful | K20: =K12 -> 0 | L20: =L12 -> 0 | M20: =M12 -> 0 | N20: =N12 -> 0 | O20: =O12 -> 0 | P20: =P12 -> 0 | Q20: =Q12 -> 0
J21: Unsuccessful | K21: =K13 -> 0 | L21: =L13 -> 0 | M21: =M13 -> 0 | N21: =N13 -> 0 | O21: =O13 -> 0 | P21: =P13 -> 0 | Q21: =Q13 -> 0
J22: Success rate | K22: =K20/(K20+K21) -> #DIV/0! | L22: =L20/(L20+L21) -> #DIV/0! | M22: =M20/(M20+M21) -> #DIV/0! | N22: =N20/(N20+N21) -> #DIV/0! | O22: =O20/(O20+O21) -> #DIV/0! | P22: =P20/(P20+P21) -> #DIV/0! | Q22: =Q20/(Q20+Q21) -> #DIV/0!
J23: Avg sale | K23: =K19/K20 -> #DIV/0! | L23: =L19/L20 -> #DIV/0! | M23: =M19/M20 -> #DIV/0! | N23: =N19/N20 -> #DIV/0! | O23: =O19/O20 -> #DIV/0! | P23: =P19/P20 -> #DIV/0! | Q23: =Q19/Q20 -> #DIV/0!
B26: JOB DETAILS | F26: JOB AMOUNT | K26: PHOTOS | N26: QUOTE | Q26: INVOICE | U26: NOTES
B27: JOB STATUS | C27: DATE | D27: JOB # | E27: SUBURB | F27: AMOUNT EXC. GST | G27: MATERIALS | H27: Merchant Fees | I27: NET PROFIT | J27: PAID | K27: BEFORE | L27: AFTER | M27: RECEIPT | N27: DESCRIPTION | O27: SIGNED | P27: EMAILED | Q27: DESCRIPTION | R27: SIGNED | S27: EMAILED | T27: 5 Star Review | V27: EFTPOS | W27: CASH | X27: Payment Plan
B28: COMPLETED & PAID JOBS
B29: 1 | I29: =F29-G29-H29 -> 0
B30: =B29+1 -> 2 | I30: =F30-G30-H30 -> 0
B31: =B30+1 -> 3 | I31: =F31-G31-H31 -> 0
B32: =B31+1 -> 4 | I32: =F32-G32-H32 -> 0
B33: =B32+1 -> 5 | I33: =F33-G33-H33 -> 0
B34: =B33+1 -> 6 | I34: =F34-G34-H34 -> 0
B35: =B34+1 -> 7 | I35: =F35-G35-H35 -> 0
B36: =B35+1 -> 8 | I36: =F36-G36-H36 -> 0
B37: =B36+1 -> 9 | I37: =F37-G37-H37 -> 0
B38: =B37+1 -> 10 | I38: =F38-G38-H38 -> 0
B39: =B38+1 -> 11 | I39: =F39-G39-H39 -> 0
B40: =B39+1 -> 12 | I40: =F40-G40-H40 -> 0
B41: =B40+1 -> 13 | I41: =F41-G41-H41 -> 0
... B44: =B43+1 -> 16 | I44: =F44-G44-H44 -> 0
...

Sheet Mgmt Summary
B3: WEEKLY TOTALS - 6th July 2025 | I3: WEEKLY | N3: COMMISSION | O3: WEEKEND
C4: MONDAY | D4: TUESDAY | E4: WEDNESDAY | F4: THURSDAY | G4: FRIDAY | H4: ACTUAL TOTAL | I4: TARGETS[S] | J4: RUNNING BAL | K4: WEEKEND | L4: COMMISSION | M4: AWAITING PAYMENT | N4: COMPLETED & PAID | O4: AWAITING PAYMENT
B5: Mathew B | C5: ='Mathew B'!K135 -> 12985 | D5: ='Mathew B'!L135 -> 6408 | E5: ='Mathew B'!M135 -> 5090 | F5: ='Mathew B'!N135 -> 6476.5 | G5: ='Mathew B'!O135 -> 21827 | H5: ='Mathew B'!P135 -> 52786.5 | I5: 50000 | J5: =-I5+H5 -> 2786.5 | K5: ='Mathew B'!Q135 -> 0 | L5: =H5 -> 52786.5 | M5: ='Mathew B'!R135 -> 17953 | N5: =L5-M5 -> 34833.5 | O5: ='Mathew B'!S135 -> 0 | P5: ='Mathew B'!F166+'Mathew B'!F177+'Mathew B'!F181 -> 52786.5 | Q5: =H5-P5 -> 0
B6: Success rate | C6: {='Mathew B'!K138:K139} -> 0.57142857 | D6: {='Mathew B'!L138:L139} -> 0.38461538 | E6: {='Mathew B'!M138:M139} -> 0.42857143 | F6: {='Mathew B'!N138:N139} -> 0.625 | G6: {='Mathew B'!O138:O139} -> 0.6 | H6: {='Mathew B'!P138:P139} -> 0.51111111 | K6: {='Mathew B'!Q138:Q139} -> #DIV/0!
B7: Avg sale | C7: 3246.25 | D7: 1281.6 | E7: 1696.6667 | F7: 1295.3 | G7: 3637.8333 | H7: 2295.0652 | K7: #DIV/0!
B8: Ben | C8: ='Ben - No OT'!K101 -> 8233 | D8: ='Ben - No OT'!L101 -> 4080 | E8: ='Ben - No OT'!M101 -> 16035 | F8: ='Ben - No OT'!N101 -> 1138 | G8: ='Ben - No OT'!O101 -> 2457.05 | H8: ='Ben - No OT'!P101 -> 31943.05 | I8: 25000 | J8: =-I8+H8 -> 6943.05 | K8: ='Ben - No OT'!Q101 -> 3206 | L8: =H8 -> 31943.05 | M8: ='Ben - No OT'!R101 -> 18484 | N8: =L8-M8 -> 13459.05 | O8: ='Ben - No OT'!S101 -> 0 | P8: ='Ben - No OT'!F122+'Ben - No OT'!F142+'Ben - No OT'!F147 -> 31943.05 | Q8: =H8-P8 -> 0
B9: Success rate | C9: {='Ben - No OT'!K104:K105} -> 0.71428571 | D9: {='Ben - No OT'!L104:L105} -> 0.5 | E9: {='Ben - No OT'!M104:M105} -> 0.6 | F9: {='Ben - No OT'!N104:N105} -> 0.33333333 | G9: {='Ben - No OT'!O104:O105} -> 0.5 | H9: {='Ben - No OT'!P104:P105} -> 0.55555556 | K9: {='Ben - No OT'!Q104:Q105} -> 0.6
B10: Avg sale | C10: 1646.6 | D10: 1360 | E10: 5345 | F10: 1138 | G10: 819.01667 | H10: 2129.5367 | K10: 1068.6667
B11: Shaun | C11: ='Shaun - No OT'!K97 -> 14401.8 | D11: ='Shaun - No OT'!L97 -> 5240.7 | E11: ='Shaun - No OT'!M97 -> 4785 | F11: ='Shaun - No OT'!N97 -> 16173 | G11: ='Shaun - No OT'!O97 -> 5060 | H11: ='Shaun - No OT'!P97 -> 45660.5 | I11: 25000 | J11: =-I11+H11 -> 20660.5 | K11: ='Shaun - No OT'!Q97 -> 0 | L11: =H11 -> 45660.5 | M11: ='Shaun - No OT'!R97 -> 12814 | N11: =L11-M11 -> 32846.5 | O11: ='Shaun - No OT'!S97 -> 0 | P11: ='Shaun - No OT'!F124+'Shaun - No OT'!F133 -> 45660.5 | Q11: =H11-P11 -> 0
B12: Success rate | C12: {='Shaun - No OT'!K100:K101} -> 0.57142857 | D12: {='Shaun - No OT'!L100:L101} -> 0.22222222 | E12: {='Shaun - No OT'!M100:M101} -> 0.625 | F12: {='Shaun - No OT'!N100:N101} -> 0.5 | G12: {='Shaun - No OT'!O100:O101} -> 0.42857143 | H12: {='Shaun - No OT'!P100:P101} -> 0.46153846 | K12: {='Shaun - No OT'!Q100:Q101} -> #DIV/0!
B13: Avg sale | C13: 3600.45 | D13: 2620.35 | E13: 957 | F13: 4043.25 | G13: 1686.6667 | H13: 2536.6944 | K13: #DIV/0!
B14: Jack M | C14: ='Jack M'!K113 -> 4952 | E14: ='Jack M'!M113 -> 18356 | F14: ='Jack M'!N113 -> 0 | G14: ='Jack M'!O113 -> 23016 | H14: ='Jack M'!P113 -> 46324 | I14: 25000 | J14: =-I14+H14 -> 21324 | K14: ='Jack M'!Q113 -> 0 | L14: =H14 -> 46324 | M14: ='Jack M'!R113 -> 35171 | N14: =L14-M14 -> 11153 | O14: ='Jack M'!S113 -> 0 | P14: ='Jack M'!F130+'Jack M'!F142+'Jack M'!F147 -> 46324 | Q14: =H14-P14 -> 0
B15: Success rate | C15: {='Jack M'!K116:K117} -> 0.5 | E15: {='Jack M'!M116:M117} -> 0.42857143 | F15: {='Jack M'!N116:N117} -> 0 | G15: {='Jack M'!O116:O117} -> 0.85714286 | H15: {='Jack M'!P116:P117} -> 0.46153846 | K15: {='Jack M'!Q116:Q117} -> #DIV/0!
B16: Avg sale | C16: 1650.6667 | E16: 6118.6667 | F16: #DIV/0! | G16: 3836 | H16: 3860.3333 | K16: #DIV/0!
B17: Liam | C17: =Liam!K103 -> 4285 | D17: =Liam!L103 -> 5475 | E17: =Liam!M103 -> 21959 | F17: =Liam!N103 -> 1025 | G17: =Liam!O103 -> 6238 | H17: =Liam!P103 -> 38982 | I17: 25000 | J17: =-I17+H17 -> 13982 | K17: =Liam!Q103 -> 0 | L17: =H17 -> 38982 | M17: =Liam!R103 -> 17756 | N17: =L17-M17 -> 21226 | O17: =Liam!S103 -> 0 | P17: =Liam!F124+Liam!F134+Liam!F138 -> 38982 | Q17: =H17-P17 -> 0
B18: Success rate | C18: {=Liam!K106:K107} -> 0.33333333 | D18: {=Liam!L106:L107} -> 0.33333333 | E18: {=Liam!M106:M107} -> 0.75 | F18: {=Liam!N106:N107} -> 0.25 | G18: {=Liam!O106:O107} -> 0.27272727 | H18: {=Liam!P106:P107} -> 0.4 | K18: {=Liam!Q106:Q107} -> #DIV/0!
B19: Avg sale | C19: 2142.5 | D19: 2737.5 | E19: 3659.8333 | F19: 1025 | G19: 2079.3333 | H19: 2784.4286 | K19: #DIV/0!
B20: Rhys C | E20: =+'Rhys C'!M19 -> 2935 | H20: =+'Rhys C'!P19 -> 2935 | I20: 25000 | J20: =-I20+H20 -> -22065 | K20: =+'Rhys C'!Q19 -> 0 | L20: =H20 -> 2935 | M20: =+'Rhys C'!R19 -> 0 | N20: =L20-M20 -> 2935 | O20: =+'Rhys C'!S19 -> 0 | P20: =+'Rhys C'!P19 -> 2935 | Q20: =H20-P20 -> 0
B21: Success rate | E21: =+'Rhys C'!M22 -> 1 | H21: =+'Rhys C'!P22 -> 1 | K21: =+'Rhys C'!Q14 -> #DIV/0!
B22: Avg sale | E22: =+'Rhys C'!M23 -> 2935 | H22: =+'Rhys C'!P23 -> 2935 | K22: =+'Rhys C'!Q15 -> #DIV/0!
B23: TOTAL | C23: =C5+C8+C20+C11+C14+C17 -> 44856.8 | D23: =D5+D8+D20+D11+D14+D17 -> 21203.7 | E23: =E5+E8+E20+E11+E14+E17 -> 69160 | F23: =F5+F8+F20+F11+F14+F17 -> 24812.5 | G23: =G5+G8+G20+G11+G14+G17 -> 58598.05 | H23: =H5+H8+H20+H11+H14+H17 -> 218631.05 | I23: =I5+I8+I20+I11+I14+I17 -> 175000 | J23: =J5+J8+J20+J11+J14+J17 -> 43631.05 | ... O23: =O5+O8+O20+O11+O14+O17 -> 0
B24: *Pending Materials Costs & Merchant Fees | H24: =H23+K23 -> 221837.05 | I24: =I23+J23 -> 218631.05 | M24: =L23-N23 -> 102178 | P24: ='Ben - No OT'!P101+'Jack M'!P113+Liam!P103+'Mathew B'!P135+'Shaun - No OT'!P97+'Rhys C'!P19 -> 218631.05 | Q24: ='Ben - No OT'!Q101+'Jack M'!Q113+Liam!Q103+'Mathew B'!Q135+'Shaun - No OT'!Q97 -> 3206 | R24: ='Ben - No OT'!R101+'Jack M'!R113+Liam!R103+'Mathew B'!R135+'Shaun - No OT'!R97 -> 102178
P25: =P24+Q24 -> 221837.05
B27: WEEKLY TOTALS - 13th July 2025 | I27: WEEKLY | N27: COMMISSION | O27: WEEKEND
C28: MONDAY | D28: TUESDAY | E28: WEDNESDAY | F28: THURSDAY | G28: FRIDAY | H28: ACTUAL TOTAL | I28: TARGETS[S] | J28: RUNNING BAL | K28: WEEKEND | L28: COMMISSION | M28: AWAITING PAYMENT | N28: COMPLETED & PAID | O28: AWAITING PAYMENT
B29: Mathew B | C29: ='Mathew B'!K244 -> 2035 | D29: ='Mathew B'!L244 -> 1734 | E29: ='Mathew B'!M244 -> 12121 | F29: ='Mathew B'!N244 -> 11723 | G29: ='Mathew B'!O244 -> 11872 | H29: ='Mathew B'!P244 -> 39485 | I29: 50000 | J29: =-I29+H29 -> -10515 | L29: =H29 -> 39485 | M29: ='Mathew B'!R244 -> 17223 | N29: =L29-M29 -> 22262 | O29: ='Mathew B'!S244 -> 0 | P29: ='Mathew B'!F271+'Mathew B'!F283+'Mathew B'!F288 -> 39485 | Q29: =H29-P29 -> 0
B30: Success rate | C30: {='Mathew B'!K247:K248} -> 0.1 | D30: {='Mathew B'!L247:L248} -> 0.4 | E30: {='Mathew B'!M247:M248} -> 0.5 | F30: {='Mathew B'!N247:N248} -> 0.5 | G30: {='Mathew B'!O247:O248} -> 0.54545455 | H30: {='Mathew B'!P247:P248} -> 0.41666667
B31: Avg sale | C31: 2035 | D31: 867 | E31: 2020.1667 | F31: 2344.6 | G31: 1978.6667 | H31: 1974.25
B32: Ben | C32: ='Ben - No OT'!K203 -> 3003 | D32: ='Ben - No OT'!L203 -> 481 | E32: ='Ben - No OT'!M203 -> 8094 | F32: ='Ben - No OT'!N203 -> 2399 | G32: ='Ben - No OT'!O203 -> 15264 | H32: ='Ben - No OT'!P203 -> 29241 | I32: 25000 | J32: =-I32+H32 -> 4241 | K32: ='Ben - No OT'!Q203 -> 3786 | L32: =H32 -> 29241 | M32: ='Ben - No OT'!R203 -> 9043 | N32: =L32-M32 -> 20198 | O32: ='Ben - No OT'!S203 -> 0 | P32: ='Ben - No OT'!F226+'Ben - No OT'!F243+'Ben - No OT'!F247 -> 29241 | Q32: =H32-P32 -> 0
B33: Success rate | C33: {='Ben - No OT'!K206:K207} -> 0.75 | D33: {='Ben - No OT'!L206:L207} -> 0.25 | E33: {='Ben - No OT'!M206:M207} -> 0.36363636 | F33: {='Ben - No OT'!N206:N207} -> 0.28571429 | G33: {='Ben - No OT'!O206:O207} -> 0.55555556 | H33: {='Ben - No OT'!P206:P207} -> 0.42857143 | K33: {='Ben - No OT'!Q206:Q207} -> 0.6
B34: Avg sale | C34: 1001 | D34: 481 | E34: 2023.5 | F34: 1199.5 | G34: 3052.8 | H34: 1949.4 | K34: 1262
B35: Shaun | C35: ='Shaun - No OT'!K191 -> 8656 | D35: ='Shaun - No OT'!L191 -> 8938 | H35: ='Shaun - No OT'!P191 -> 17594 | I35: 25000 | J35: =-I35+H35 -> -7406 | L35: =H35 -> 17594 | M35: ='Shaun - No OT'!R191 -> 0 | N35: =L35-M35 -> 17594 | O35: ='Shaun - No OT'!S191 -> 0 | P35: ='Shaun - No OT'!F207 -> 17594 | Q35: =H35-P35 -> 0
B36: Success rate | C36: {='Shaun - No OT'!K194:K195} -> 0.5 | D36: {='Shaun - No OT'!L194:L195} -> 0.75 | H36: {='Shaun - No OT'!P194:P195} -> 0.6
B37: Avg sale | C37: 2885.3333 | D37: 2979.3333 | H37: 2932.3333
B38: Jack M | C38: ='Jack M'!K192 -> 3672 | D38: ='Jack M'!L192 -> 1138 | H38: ='Jack M'!P192 -> 4810 | I38: 25000 | J38: =-I38+H38 -> -20190 | L38: =H38 -> 4810 | M38: ='Jack M'!R192 -> 0 | N38: =L38-M38 -> 4810 | O38: ='Jack M'!S192 -> 0 | P38: ='Jack M'!F206 -> 4810 | Q38: =H38-P38 -> 0
B39: Success rate | C39: {='Jack M'!K195:K196} -> 0.375 | D39: {='Jack M'!L195:L196} -> 0.14285714 | H39: {='Jack M'!P195:P196} -> 0.26666667
B40: Avg sale | C40: 1224 | D40: 1138 | H40: 1202.5
B41: Liam | C41: =Liam!K188 -> 4152 | E41: =Liam!M188 -> 7759 | F41: =Liam!N188 -> 8192 | G41: =Liam!O188 -> 3970 | H41: =Liam!P188 -> 24073 | I41: 25000 | J41: =-I41+H41 -> -927 | L41: =H41 -> 24073 | M41: =Liam!R188 -> 10131 | N41: =L41-M41 -> 13942 | O41: =Liam!S188 -> 0 | P41: =Liam!F208+Liam!F218+Liam!F224 -> 24073 | Q41: =H41-P41 -> 0
B42: Success rate | C42: {=Liam!K191:K192} -> 1 | E42: {=Liam!M191:M192} -> 0.6 | F42: {=Liam!N191:N192} -> 0.45454545 | G42: {=Liam!O191:O192} -> 0.33333333 | H42: {=Liam!P191:P192} -> 0.44117647
B43: Avg sale | C43: 1038 | E43: 2586.3333 | F43: 1638.4 | G43: 1323.3333 | H43: 1604.8667
...

Sheet Weekly Summary
H1: VIC Total | I1: No of Weeks | J1: Average
H2: =I28+I52+I79+I106+I140+I168+I199+I227+I258+I285+I313+I341+I373+I407+I443+I474+I499 -> 3906652.1 | I2: =17 -> 17 | J2: =H2/I2 -> 229803.07
C7: WEEKLY TOTALS | D7: 6th Jul 2025 | J7: WEEKLY | O7: COMMISSION | P7: WEEKEND
A8: No. of 5 Star Reviews | B8: M8 Notes | D8: MONDAY | E8: TUESDAY | F8: WEDNESDAY | G8: THURSDAY | H8: FRIDAY | I8: ACTUAL TOTAL | J8: TARGETS[S] | K8: RUNNING BAL | L8: WEEKEND | M8: COMMISSION | N8: AWAITING PAYMENT | O8: COMPLETED & PAID | P8: AWAITING PAYMENT
A9: ='Ben - No OT'!T87 -> 0 | B9: ='Ben - No OT'!T88 -> 0 | C9: Ben | D9: ='Ben - No OT'!K93 -> 7859.14 | E9: ='Ben - No OT'!L93 -> 4000.6 | F9: ='Ben - No OT'!M93 -> 14266.04 | G9: ='Ben - No OT'!N93 -> 898.3 | H9: ='Ben - No OT'!O93 -> 2369.65 | I9: ='Ben - No OT'!P93 -> 29393.73 | J9: 50000 | K9: =-J9+I9 -> -20606.27 | L9: ='Ben - No OT'!Q93 -> 2903.17 | M9: =I9 -> 29393.73 | N9: ='Ben - No OT'!R93 -> 16875.34 | O9: =M9-N9 -> 12518.39 | P9: ='Ben - No OT'!S93 -> 0
C10: Success rate | D10: {='Ben - No OT'!K96:K97} -> 0.71428571 | E10: {='Ben - No OT'!L96:L97} -> 0.5 | F10: {='Ben - No OT'!M96:M97} -> 0.6 | G10: {='Ben - No OT'!N96:N97} -> 0.33333333 | H10: {='Ben - No OT'!O96:O97} -> 0.5 | I10: {='Ben - No OT'!P96:P97} -> 0.55555556 | L10: {='Ben - No OT'!Q96:Q97} -> 0.6
C11: Avg sale | D11: 1571.828 | E11: 1333.5333 | F11: 4755.3467 | G11: 898.3 | H11: 789.88333 | I11: 1959.582 | L11: 967.72333
A12: ='Jack M'!T99 -> 0 | B12: ='Jack M'!T100 -> 0 | C12: Jack M | D12: ='Jack M'!K105 -> 4069.55 | F12: ='Jack M'!M105 -> 15872.99 | G12: ='Jack M'!N105 -> 0 | H12: ='Jack M'!O105 -> 21295.65 | I12: ='Jack M'!P105 -> 41238.19 | J12: 50000 | K12: =-J12+I12 -> -8761.81 | M12: =I12 -> 41238.19 | N12: ='Jack M'!R105 -> 31148.29 | O12: =M12-N12 -> 10089.9 | P12: ='Jack M'!S105 -> 0
C13: Success rate | D13: {='Jack M'!K108:K109} -> 0.5 | F13: {='Jack M'!M108:M109} -> 0.42857143 | G13: {='Jack M'!N108:N109} -> 0 | H13: {='Jack M'!O108:O109} -> 0.85714286 | I13: {='Jack M'!P108:P109} -> 0.46153846
C14: Avg sale | D14: 1356.5167 | F14: 5290.9967 | G14: #DIV/0! | H14: 3549.275 | I14: 3436.5158
A15: =Liam!T89 -> 0 | B15: =Liam!T90 -> 1 | C15: Liam | D15: =Liam!K95 -> 3754.66 | E15: =Liam!L95 -> 5126.75 | F15: =Liam!M95 -> 20237.1 | G15: =Liam!N95 -> 985.3 | H15: =Liam!O95 -> 6198.3 | I15: =Liam!P95 -> 36302.11 | J15: 50000 | K15: =-J15+I15 -> -13697.89 | M15: =I15 -> 36302.11 | N15: =Liam!R95 -> 16113.5 | O15: =M15-N15 -> 20188.61 | P15: =Liam!S95 -> 0
C16: Success rate | D16: {=Liam!K98:K99} -> 0.33333333 | E16: {=Liam!L98:L99} -> 0.33333333 | F16: {=Liam!M98:M99} -> 0.75 | G16: {=Liam!N98:N99} -> 0.25 | H16: {=Liam!O98:O99} -> 0.27272727 | I16: {=Liam!P98:P99} -> 0.4
C17: Avg sale | D17: 1877.33 | E17: 2563.375 | F17: 3372.85 | G17: 985.3 | H17: 2066.1 | I17: 2593.0079
A18: ='Mathew B'!T121 -> 0 | B18: ='Mathew B'!T122 -> 0 | C18: Mathew B | D18: ='Mathew B'!K127 -> 9501.91 | E18: ='Mathew B'!L127 -> 5627.31 | F18: ='Mathew B'!M127 -> 4350.21 | G18: ='Mathew B'!N127 -> 6232 | H18: ='Mathew B'!O127 -> 19495.03 | I18: ='Mathew B'!P127 -> 45206.46 | J18: 50000 | K18: =-J18+I18 -> -4793.54 | M18: =I18 -> 45206.46 | N18: ='Mathew B'!R127 -> 15883.65 | O18: =M18-N18 -> 29322.81 | P18: ='Mathew B'!S127 -> 0
C19: Success rate | D19: {='Mathew B'!K130:K131} -> 0.57142857 | E19: {='Mathew B'!L130:L131} -> 0.38461538 | F19: {='Mathew B'!M130:M131} -> 0.42857143 | G19: {='Mathew B'!N130:N131} -> 0.625 | H19: {='Mathew B'!O130:O131} -> 0.6 | I19: {='Mathew B'!P130:P131} -> 0.51111111
C20: Avg sale | D20: 2375.4775 | E20: 1125.462 | F20: 1450.07 | G20: 1246.4 | H20: 3249.1717 | I20: 1965.4983
A21: ='Shaun - No OT'!T83 -> 0 | B21: ='Shaun - No OT'!T84 -> 0 | C21: Shaun | D21: ='Shaun - No OT'!K89 -> 11178.03 | E21: ='Shaun - No OT'!L89 -> 4307.26 | F21: ='Shaun - No OT'!M89 -> 4665.9 | G21: ='Shaun - No OT'!N89 -> 14856.52 | H21: ='Shaun - No OT'!O89 -> 4965.57 | I21: ='Shaun - No OT'!P89 -> 39973.28 | J21: 50000 | K21: =-J21+I21 -> -10026.72 | M21: =I21 -> 39973.28 | N21: ='Shaun - No OT'!R89 -> 11576.92 | O21: =M21-N21 -> 28396.36 | P21: ='Shaun - No OT'!S89 -> 0
C22: Success rate | D22: {='Shaun - No OT'!K92:K93} -> 0.57142857 | E22: {='Shaun - No OT'!L92:L93} -> 0.22222222 | F22: {='Shaun - No OT'!M92:M93} -> 0.625 | G22: {='Shaun - No OT'!N92:N93} -> 0.5 | H22: {='Shaun - No OT'!O92:O93} -> 0.42857143 | I22: {='Shaun - No OT'!P92:P93} -> 0.46153846
C23: Avg sale | D23: 2794.5075 | E23: 2153.63 | F23: 933.18 | G23: 3714.13 | H23: 1655.19 | I23: 2220.7378
A24: =+'Rhys C'!T5 -> 0 | B24: =+'Rhys C'!T6 -> 0 | C24: Rhys C | F24: =+'Rhys C'!M11 -> 2202.59 | I24: =+'Rhys C'!P11 -> 2202.59 | J24: 50000 | K24: =-J24+I24 -> -47797.41 | M24: =I24 -> 2202.59 | N24: =+'Rhys C'!R11 -> 0 | O24: =M24-N24 -> 2202.59 | P24: =+'Rhys C'!S11 -> 0
C25: Success rate | F25: =+'Rhys C'!M14 -> 1 | I25: =+'Rhys C'!P14 -> 1
C26: Avg sale | F26: =+'Rhys C'!M15 -> 2202.59 | I26: =+'Rhys C'!P15 -> 2202.59
A27: =SUM(A12:A26) -> 0 | B27: =SUM(B12:B26) -> 1 | C27: TOTAL | D27: =D12+D18++D9+D21+D15+D24 -> 36363.29 | E27: =E12+E18++E9+E21+E15+E24 -> 19061.92 | F27: =F12+F18++F9+F21+F15+F24 -> 61594.83 | G27: =G12+G18++G9+G21+G15+G24 -> 22972.12 | H27: =H12+H18++H9+H21+H15+H24 -> 54324.2 | I27: =I12+I18++I9+I21+I15+I24 -> 194316.36 | J27: =J12+J18++J9+J21+J15+J24 -> 300000 | K27: =K12+K18++K9+K21+K15+K24 -> -105683.64 | ... P27: =P12+P18++P9+P21+P15+P24 -> 0
I28: =I27+L27 -> 197219.53 | J28: =J27+K27 -> 194316.36 | N28: =M27-O27 -> 91597.7 | R28: ='Ben - No OT'!P93+'Jack M'!P105+Liam!P95+'Mathew B'!P127+'Shaun - No OT'!P89+'Rhys C'!P11 -> 194316.36 | S28: ='Ben - No OT'!Q93+'Jack M'!Q105+Liam!Q95+'Mathew B'!Q127+'Shaun - No OT'!Q89 -> 2903.17 | T28: ='Ben - No OT'!R93+'Jack M'!R105+Liam!R95+'Mathew B'!R127+'Shaun - No OT'!R89 -> 91597.7
R29: =R28+S28 -> 197219.53
C31: WEEKLY TOTALS | D31: 13th Jul 2025 | J31: WEEKLY | O31: COMMISSION | P31: WEEKEND
A32: No. of 5 Star Reviews | B32: M8 Notes | D32: MONDAY | E32: TUESDAY | F32: WEDNESDAY | G32: THURSDAY | H32: FRIDAY | I32: ACTUAL TOTAL | J32: TARGETS[S] | K32: RUNNING BAL | L32: WEEKEND | M32: COMMISSION | N32: AWAITING PAYMENT | O32: COMPLETED & PAID | P32: AWAITING PAYMENT
A33: ='Ben - No OT'!T189 -> 0 | B33: ='Ben - No OT'!T190 -> 0 | C33: Ben | D33: ='Ben - No OT'!K195 -> 2719.58 | E33: ='Ben - No OT'!L195 -> 474.48 | F33: ='Ben - No OT'!M195 -> 7489.47 | G33: ='Ben - No OT'!N195 -> 2319.6 | H33: ='Ben - No OT'!O195 -> 13838.92 | I33: ='Ben - No OT'!P195 -> 26842.05 | J33: 50000 | K33: =-J33+I33 -> -23157.95 | L33: ='Ben - No OT'!Q195 -> 3666.9 | M33: =I33 -> 26842.05 | N33: ='Ben - No OT'!R195 -> 8057.79 | O33: =M33-N33 -> 18784.26 | P33: ='Ben - No OT'!S195 -> 0
C34: Success rate | D34: {='Ben - No OT'!K198:K199} -> 0.75 | E34: {='Ben - No OT'!L198:L199} -> 0.25 | F34: {='Ben - No OT'!M198:M199} -> 0.36363636 | G34: {='Ben - No OT'!N198:N199} -> 0.28571429 | H34: {='Ben - No OT'!O198:O199} -> 0.55555556 | I34: {='Ben - No OT'!P198:P199} -> 0.42857143 | L34: {='Ben - No OT'!Q198:Q199} -> 0.6
C35: Avg sale | D35: 906.52667 | E35: 474.48 | F35: 1872.3675 | G35: 1159.8 | H35: 2767.784 | I35: 1789.47 | L35: 1222.3
A36: ='Jack M'!T178 -> 0 | B36: ='Jack M'!T179 -> 0 | C36: Jack M | D36: ='Jack M'!K184 -> 3632.3 | E36: ='Jack M'!L184 -> 1098.3 | I36: ='Jack M'!P184 -> 4730.6 | J36: 50000 | K36: =-J36+I36 -> -45269.4 | M36: =I36 -> 4730.6 | N36: ='Jack M'!R184 -> 0 | O36: =M36-N36 -> 4730.6 | P36: ='Jack M'!S184 -> 0
C37: Success rate | D37: {='Jack M'!K187:K188} -> 0.375 | E37: {='Jack M'!L187:L188} -> 0.14285714 | I37: {='Jack M'!P187:P188} -> 0.26666667
C38: Avg sale | D38: 1210.7667 | E38: 1098.3 | I38: 1182.65
A39: =Liam!T174 -> 0 | B39: =Liam!T175 -> 0 | C39: Liam | D39: =Liam!K180 -> 4032.9 | F39: =Liam!M180 -> 5662.66 | G39: =Liam!N180 -> 7286.51 | H39: =Liam!O180 -> 3809.61 | I39: =Liam!P180 -> 20791.68 | J39: 50000 | K39: =-J39+I39 -> -29208.32 | M39: =I39 -> 20791.68 | N39: =Liam!R180 -> 7755.26 | O39: =M39-N39 -> 13036.42 | P39: =Liam!S180 -> 0
C40: Success rate | D40: {=Liam!K183:K184} -> 1 | F40: {=Liam!M183:M184} -> 0.6 | G40: {=Liam!N183:N184} -> 0.45454545 | H40: {=Liam!O183:O184} -> 0.33333333 | I40: {=Liam!P183:P184} -> 0.44117647
C41: Avg sale | D41: 1008.225 | F41: 1887.5533 | G41: 1457.302 | H41: 1269.87 | I41: 1386.112
A42: ='Mathew B'!T230 -> 1 | B42: ='Mathew B'!T231 -> 0 | C42: Mathew B | D42: ='Mathew B'!K236 -> 1588.3 | E42: ='Mathew B'!L236 -> 1656.2 | F42: ='Mathew B'!M236 -> 9922.5 | G42: ='Mathew B'!N236 -> 9507.85 | H42: ='Mathew B'!O236 -> 11337.74 | I42: ='Mathew B'!P236 -> 34012.59 | J42: 50000 | K42: =-J42+I42 -> -15987.41 | M42: =I42 -> 34012.59 | N42: ='Mathew B'!R236 -> 14469.71 | O42: =M42-N42 -> 19542.88 | P42: ='Mathew B'!S236 -> 0
C43: Success rate | D43: {='Mathew B'!K239:K240} -> 0.1 | E43: {='Mathew B'!L239:L240} -> 0.4 | F43: {='Mathew B'!M239:M240} -> 0.5 | G43: {='Mathew B'!N239:N240} -> 0.5 | H43: {='Mathew B'!O239:O240} -> 0.54545455 | I43: {='Mathew B'!P239:P240} -> 0.41666667
C44: Avg sale | D44: 1588.3 | E44: 828.1 | F44: 1653.75 | G44: 1901.57 | H44: 1889.6233 | I44: 1700.6295
A45: ='Shaun - No OT'!T177 -> 0 | B45: ='Shaun - No OT'!T178 -> 0 | C45: Shaun | D45: ='Shaun - No OT'!K183 -> 7299.83 | E45: ='Shaun - No OT'!L183 -> 7415.25 | I45: ='Shaun - No OT'!P183 -> 14715.08 | J45: 50000 | K45: =-J45+I45 -> -35284.92 | M45: =I45 -> 14715.08 | N45: ='Shaun - No OT'!R183 -> 0 | O45: =M45-N45 -> 14715.08 | P45: ='Shaun - No OT'!S183 -> 0
...

Sheet Aden
B3: WEEKLY COMMISSION | F3: WEEK ENDING | G3: 45886
K4: PHOTOS | N4: QUOTE | Q4: INVOICE
B5: BOOKED JOBS | C5: =C6+C7 -> 1 | E5: WEEKLY TARGET | K5: BEFORE | L5: AFTER | M5: RECEIPT | N5: DESCRIPTION | O5: SIGNED | P5: EMAILED | Q5: DESCRIPTION | R5: SIGNED | S5: EMAILED | T5: 5 Star Review
B6: SUCCESSFUL | C6: =P13 -> 1 | E6: Tier 1 | F6: 0.05 | J6: TAKEN | K6: =K32 -> 0 | L6: =L32 -> 0 | M6: =M32 -> 0 | N6: =N32 -> 0 | O6: =O32 -> 0 | P6: =P32 -> 0 | Q6: =Q32 -> 0 | R6: =R32 -> 0 | S6: =S32 -> 0 | T6: =T37 -> 0
B7: UNSUCCESSFUL | C7: =P14 -> 0 | J7: % | K7: =K32/K31 -> #DIV/0! | L7: =L32/L31 -> #DIV/0! | M7: =M32/M31 -> #DIV/0! | N7: =N32/N31 -> #DIV/0! | O7: =O32/O31 -> #DIV/0! | P7: =P32/P31 -> #DIV/0! | Q7: =Q32/Q31 -> #DIV/0! | R7: =R32/R31 -> #DIV/0! | S7: =S32/S31 -> #DIV/0! | U7: M8 Notes
B8: SUCESSFUL (%) | C8: =P15 -> 1
F9: ACTUAL | G9: POTENTIAL | H9: Exc. SUPER
B10: AVERAGE SALE | C10: =P16 -> 990 | E10: NET PROFIT | F10: =P12 -> 990 | G10: =I31+I36 -> 990 | K10: DAILY NET PROFIT | R10: WEEKDAY | S10: WEEKEND
E11: UNLOCKED | F11: =F6 -> 0.05 | K11: MON | L11: TUE | M11: WED | N11: THU | O11: FRI | P11: Total | Q11: SAT | R11: Awaiting Payment | S11: Awaiting Payment
E12: COMMISSION - PAY OUT | F12: =(F10-I35)*F11 -> 0 | G12: $- | H12: =F12/1.12 -> 0 | O12: =I35 -> 990 | P12: =SUM(K12:O12) -> 990 | Q12: 0 | R12: =I36 -> 990 | S12: 0
E13: EMERGENCY | F13: =Q12 -> 0 | G13: $- | J13: Successful | O13: 1 | P13: =SUM(K13:O13) -> 1
E14: EMERGENCY - PAY OUT | F14: =F13*0.25 -> 0 | G14: $- | H14: =F14/1.12 -> 0 | J14: Unsuccessful | O14: 0 | P14: =SUM(K14:O14) -> 0
E15: PREV. WEEK | G15: $- | J15: Success rate | K15: =K13/(K13+K14) -> #DIV/0! | L15: =L13/(L13+L14) -> #DIV/0! | M15: =M13/(M13+M14) -> #DIV/0! | N15: =N13/(N13+N14) -> #DIV/0! | O15: =O13/(O13+O14) -> 1 | P15: =P13/(P13+P14) -> 1 | Q15: =Q13/(Q13+Q14) -> #DIV/0!
E16: PREV. WEEK - PAY OUT | F16: =F15*0.05 -> 0 | G16: $- | H16: =F16/1.12 -> 0 | J16: Avg sale | K16: =K12/K13 -> #DIV/0! | L16: =L12/L13 -> #DIV/0! | M16: =M12/M13 -> #DIV/0! | N16: =N12/N13 -> #DIV/0! | O16: =O12/O13 -> 990 | P16: =P12/P13 -> 990 | Q16: =Q12/Q13 -> #DIV/0!
E17: 5 Star Review | H17: =F17/1.12 -> 0
E18: 5 Star Notes | F18: =T7 -> 0 | K18: Managment Summary - SALES ONLY - COLUMN F | R18: WEEKDAY | S18: WEEKEND
K19: MON | L19: TUE | M19: WED | N19: THU | O19: FRI | P19: Total | Q19: SAT | R19: Awaiting Payment | S19: Awaiting Payment
O20: =F35 -> 1675 | P20: =SUM(K20:O20) -> 1675 | Q20: 0 | R20: =+F36 -> 1675 | S20: 0
J21: Successful | K21: =K13 -> 0 | L21: =L13 -> 0 | M21: =M13 -> 0 | N21: =N13 -> 0 | O21: =O13 -> 1 | P21: =P13 -> 1 | Q21: =Q13 -> 0
J22: Unsuccessful | K22: =K14 -> 0 | L22: =L14 -> 0 | M22: =M14 -> 0 | N22: =N14 -> 0 | O22: =O14 -> 0 | P22: =P14 -> 0 | Q22: =Q14 -> 0
J23: Success rate | K23: =K21/(K21+K22) -> #DIV/0! | L23: =L21/(L21+L22) -> #DIV/0! | M23: =M21/(M21+M22) -> #DIV/0! | N23: =N21/(N21+N22) -> #DIV/0! | O23: =O21/(O21+O22) -> 1 | P23: =P21/(P21+P22) -> 1 | Q23: =Q21/(Q21+Q22) -> #DIV/0!
J24: Avg sale | K24: =K20/K21 -> #DIV/0! | L24: =L20/L21 -> #DIV/0! | M24: =M20/M21 -> #DIV/0! | N24: =N20/N21 -> #DIV/0! | O24: =O20/O21 -> 1675 | P24: =P20/P21 -> 1675 | Q24: =Q20/Q21 -> #DIV/0!
B27: JOB DETAILS | F27: JOB AMOUNT | K27: PHOTOS | N27: QUOTE | Q27: INVOICE | U27: NOTES
B28: JOB STATUS | C28: DATE | D28: JOB # | E28: SUBURB | F28: AMOUNT EXC. GST | G28: MATERIALS | H28: Merchant Fees | I28: NET PROFIT | J28: PAID | K28: BEFORE | L28: AFTER | M28: RECEIPT | N28: DESCRIPTION | O28: SIGNED | P28: EMAILED | Q28: DESCRIPTION | R28: SIGNED | S28: EMAILED | T28: 5 Star Review | V28: EFTPOS | W28: CASH | X28: Payment Plan
B29: COMPLETED & PAID JOBS
B30: 1 | I30: =F30-G30-H30 -> 0
F31: =SUM(F30:F30) -> 0 | G31: =SUM(G30:G30) -> 0 | H31: =SUM(H30:H30) -> 0 | I31: =SUM(I30:I30) -> 0 | K31: =COUNT(K30:K30) -> 0 | L31: =COUNT(L30:L30) -> 0 | M31: =COUNT(M30:M30) -> 0 | N31: =COUNT(N30:N30) -> 0 | O31: =COUNT(O30:O30) -> 0 | P31: =COUNT(P30:P30) -> 0 | Q31: =COUNT(Q30:Q30) -> 0 | R31: =COUNT(R30:R30) -> 0 | S31: =COUNT(S30:S30) -> 0
K32: =SUM(K30:K30) -> 0 | L32: =SUM(L30:L30) -> 0 | M32: =SUM(M30:M30) -> 0 | N32: =SUM(N30:N30) -> 0 | O32: =SUM(O30:O30) -> 0 | P32: =SUM(P30:P30) -> 0 | Q32: =SUM(Q30:Q30) -> 0 | R32: =SUM(R30:R30) -> 0 | S32: =SUM(S30:S30) -> 0
B34: CURRENT WORK ORDERS (AWAITING PAYMENT)
A35: 45887 | B35: 1 | C35: 45884 | D35: 72353 | E35: Dandenong North | F35: 1675 | G35: =485+200 -> 685 | I35: =F35-G35-H35 -> 990 | J35: Cash | K35: 1 | L35: 1 | M35: 1 | N35: 1 | O35: 1 | P35: 0 | Q35: 1 | R35: 1 | S35: 0 | U35: 18/8-WIP by Rhys | W35: =200+1457 -> 1657
F36: =SUM(F35:F35) -> 1675 | G36: =SUM(G35:G35) -> 685 | H36: =SUM(H35:H35) -> 0 | I36: =SUM(I35:I35) -> 990
T37: =SUM(T30:T36) -> 0 | V37: =SUM(V30:V36) -> 0 | W37: =SUM(W30:W36) -> 1657 | X37: =SUM(X30:X36) -> 0
B40: WEEKLY COMMISSION | F40: WEEK ENDING | G40: 45893
K41: PHOTOS | N41: QUOTE | Q41: INVOICE
B42: BOOKED JOBS | C42: =C43+C44 -> 0 | E42: WEEKLY TARGET | K42: BEFORE | L42: AFTER | M42: RECEIPT | N42: DESCRIPTION | O42: SIGNED | P42: EMAILED | Q42: DESCRIPTION | R42: SIGNED | S42: EMAILED | T42: 5 Star Review
B43: SUCCESSFUL | C43: =P50 -> 0 | E43: Tier 1 | F43: 0.05 | J43: TAKEN | K43: =K69 -> 0 | L43: =L69 -> 0 | M43: =M69 -> 0 | N43: =N69 -> 0 | O43: =O69 -> 0 | P43: =P69 -> 0 | Q43: =Q69 -> 0 | R43: =R69 -> 0 | S43: =S69 -> 0 | T43: =T73 -> 0
B44: UNSUCCESSFUL | C44: =P51 -> 0 | J44: % | K44: =K69/K68 -> #DIV/0! | L44: =L69/L68 -> #DIV/0! | M44: =M69/M68 -> #DIV/0! | N44: =N69/N68 -> #DIV/0! | O44: =O69/O68 -> #DIV/0! | P44: =P69/P68 -> #DIV/0! | Q44: =Q69/Q68 -> #DIV/0! | R44: =R69/R68 -> #DIV/0! | S44: =S69/S68 -> #DIV/0! | U44: M8 Notes
B45: SUCESSFUL (%) | C45: =P52 -> #DIV/0!
F46: ACTUAL | G46: POTENTIAL | H46: Exc. SUPER
B47: AVERAGE SALE | C47: =P53 -> #DIV/0! | E47: NET PROFIT | F47: =P49 -> 0 | G47: =I68 -> 0 | K47: DAILY NET PROFIT | R47: WEEKDAY | S47: WEEKEND
...

Sheet Ben - No OT
B3: WEEKLY COMMISSION | F3: WEEK ENDING | G3: 45837
K4: PHOTOS | N4: QUOTE | Q4: INVOICE
B5: BOOKED JOBS | C5: =C6+C7 -> 28 | E5: WEEKLY TARGET | K5: BEFORE | L5: AFTER | M5: RECEIPT | N5: DESCRIPTION | O5: SIGNED | P5: EMAILED | Q5: DESCRIPTION | R5: SIGNED | S5: EMAILED | T5: 5 Star Review
B6: SUCCESSFUL | C6: =P13 -> 15 | E6: Tier 1 | F6: 0.05 | J6: TAKEN | K6: =K39 -> 8 | L6: =L39 -> 7 | M6: =M39 -> 7 | N6: =N39 -> 8 | O6: =O39 -> 8 | P6: =P39 -> 5 | Q6: =Q39 -> 8 | R6: =R39 -> 7 | S6: =S39 -> 6 | T6: =T80 -> 2
B7: UNSUCCESSFUL | C7: =P14 -> 13 | J7: % | K7: =K39/K38 -> 1 | L7: =L39/L38 -> 0.875 | M7: =M39/M38 -> 0.875 | N7: =N39/N38 -> 1 | O7: =O39/O38 -> 1 | P7: =P39/P38 -> 0.625 | Q7: =Q39/Q38 -> 1 | R7: =R39/R38 -> 0.875 | S7: =S39/S38 -> 0.75 | U7: M8 Notes
B8: SUCESSFUL (%) | C8: =P15 -> 0.53571429
F9: ACTUAL | G9: POTENTIAL | H9: Exc. SUPER
B10: AVERAGE SALE | C10: =P16 -> 2164.764 | E10: NET PROFIT | F10: =P12 -> 32471.46 | G10: =I38+I48+I52 -> 32471.46 | K10: DAILY NET PROFIT | R10: WEEKDAY | S10: WEEKEND
E11: UNLOCKED | F11: =F6 -> 0.05 | K11: MON | L11: TUE | M11: WED | N11: THU | O11: FRI | P11: Total | Q11: SAT | R11: Awaiting Payment | S11: Awaiting Payment
E12: COMMISSION - PAY OUT | F12: =(F10+F19-I37-I36-I42-I43-I44-I45-I46-I47-I51)*F11 -> 615.15 | G12: $- | H12: =F12/1.12 -> 549.24107 | K12: =I30+I31+I42 -> 4595.05 | L12: =I43+I32+I44 -> 6204.86 | M12: =I34+I45+I33+I46 -> 9344.35 | N12: =I35+I51 -> 7726.6 | O12: =I36+I37+I47 -> 4600.6 | P12: =SUM(K12:O12) -> 32471.46 | Q12: 0 | R12: =I48+I52 -> 17939.16 | S12: 0
E13: EMERGENCY | F13: =Q12 -> 0 | G13: $- | J13: Successful | K13: 3 | L13: 3 | M13: 4 | N13: 2 | O13: 3 | P13: =SUM(K13:O13) -> 15
E14: EMERGENCY - PAY OUT | F14: =F13*0.25 -> 0 | G14: $- | H14: =F14/1.12 -> 0 | J14: Unsuccessful | K14: 2 | L14: 2 | M14: 1 | N14: 2 | O14: 6 | P14: =SUM(K14:O14) -> 13
E15: PREV. WEEK | G15: $- | J15: Success rate | K15: =K13/(K13+K14) -> 0.6 | L15: =L13/(L13+L14) -> 0.6 | M15: =M13/(M13+M14) -> 0.8 | N15: =N13/(N13+N14) -> 0.5 | O15: =O13/(O13+O14) -> 0.33333333 | P15: =P13/(P13+P14) -> 0.53571429 | Q15: =Q13/(Q13+Q14) -> #DIV/0!
E16: PREV. WEEK - PAY OUT | F16: =F15*0.05 -> 0 | G16: $- | H16: =F16/1.12 -> 0 | J16: Avg sale | K16: =K12/K13 -> 1531.6833 | L16: =L12/L13 -> 2068.2867 | M16: =M12/M13 -> 2336.0875 | N16: =N12/N13 -> 3863.3 | O16: =O12/O13 -> 1533.5333 | P16: =P12/P13 -> 2164.764 | Q16: =Q12/Q13 -> #DIV/0!
E17: 5 Star Review | F17: =1*50 -> 50 | H17: =F17/1.12 -> 44.642857
E18: 5 Star Notes | F18: =T7 -> 0 | K18: Managment Summary - SALES ONLY - COLUMN F | R18: WEEKDAY | S18: WEEKEND
E19: 16 Jun - Water Leak - Job #70792 | F19: =-450 -> -450 | K19: MON | L19: TUE | M19: WED | N19: THU | O19: FRI | P19: Total | Q19: SAT | R19: Awaiting Payment | S19: Awaiting Payment
K20: =F30+F31+F42 -> 7075 | L20: =F43+F32+F44 -> 8608 | M20: =F34+F45+F33+F46 -> 12993 | N20: =F35+F51 -> 12606 | O20: =F36+F37+F47 -> 4680 | P20: =SUM(K20:O20) -> 45962 | Q20: 0 | R20: =F48+F52 -> 26236 | S20: 0
J21: Successful | K21: =K13 -> 3 | L21: =L13 -> 3 | M21: =M13 -> 4 | N21: =N13 -> 2 | O21: =O13 -> 3 | P21: =P13 -> 15 | Q21: =Q13 -> 0
J22: Unsuccessful | K22: =K14 -> 2 | L22: =L14 -> 2 | M22: =M14 -> 1 | N22: =N14 -> 2 | O22: =O14 -> 6 | P22: =P14 -> 13 | Q22: =Q14 -> 0
J23: Success rate | K23: =K21/(K21+K22) -> 0.6 | L23: =L21/(L21+L22) -> 0.6 | M23: =M21/(M21+M22) -> 0.8 | N23: =N21/(N21+N22) -> 0.5 | O23: =O21/(O21+O22) -> 0.33333333 | P23: =P21/(P21+P22) -> 0.53571429 | Q23: =Q21/(Q21+Q22) -> #DIV/0!
J24: Avg sale | K24: =K20/K21 -> 2358.3333 | L24: =L20/L21 -> 2869.3333 | M24: =M20/M21 -> 3248.25 | N24: =N20/N21 -> 6303 | O24: =O20/O21 -> 1560 | P24: =P20/P21 -> 3064.1333 | Q24: =Q20/Q21 -> #DIV/0!
B27: JOB DETAILS | F27: JOB AMOUNT | K27: PHOTOS | N27: QUOTE | Q27: INVOICE | U27: NOTES
B28: JOB STATUS | C28: DATE | D28: JOB # | E28: SUBURB | F28: AMOUNT EXC. GST | G28: MATERIALS | H28: Merchant Fees | I28: NET PROFIT | J28: PAID | K28: BEFORE | L28: AFTER | M28: RECEIPT | N28: DESCRIPTION | O28: SIGNED | P28: EMAILED | Q28: DESCRIPTION | R28: SIGNED | S28: EMAILED | T28: 5 Star Review | V28: EFTPOS | W28: CASH | X28: Payment Plan
B29: COMPLETED & PAID JOBS
B30: 1 | C30: 45831 | D30: 70938/85882114 | E30: Reservoir | F30: 681 | I30: =F30-G30-H30 -> 681 | J30: Card | K30: 1 | L30: 1 | M30: 1 | N30: 1 | O30: 1 | P30: 0 | Q30: 1 | R30: 0 | S30: 1 | U30: 23/06 - WIP&Completed By Tolga , Ben | V30: 749.1
B31: =B30+1 -> 2 | C31: 45831 | D31: 70960 | E31: Coburg | F31: 1261 | G31: 39.7 | I31: =F31-G31-H31 -> 1221.3 | J31: Card | K31: 1 | L31: 1 | M31: 1 | N31: 1 | O31: 1 | P31: 0 | Q31: 1 | R31: 1 | S31: 0 | V31: 1387.1
B32: =B31+1 -> 3 | C32: 45832 | D32: 70985 | E32: North Melbourne | F32: 5814 | G32: =39.7+(1430.19)+250 -> 1719.89 | I32: =F32-G32-H32 -> 4094.11 | J32: Card | K32: 1 | L32: 1 | M32: 1 | N32: 1 | O32: 1 | P32: 1 | Q32: 1 | R32: 1 | S32: 1 | U32: 25/06 - WIP&Completed by Daniel C ; 24/06 - WIP by Daniel C , Ben | V32: =640+5500+255.4 -> 6395.4
B33: =B32+1 -> 4 | C33: 45833 | D33: 70918/858910127 | E33: Doncaster | F33: 7075 | G33: =39.7+(78.67)+(1.6+2365.41+143.43+41.8)+500 -> 3170.61 | I33: =F33-G33-H33 -> 3904.39 | J33: Card | K33: 1 | L33: 1 | M33: 1 | N33: 1 | O33: 1 | P33: 0 | Q33: 1 | R33: 1 | S33: 0 | U33: 26/06 - WIP&Completed by Alex ;25/06 - WIP by Jarrod , Ben ,Alex | V33: =75+674.1+783+6250.4 -> 7782.5
A34: 09/07 CB09/07 | B34: =B33+1 -> 5 | C34: 45833 | D34: 70990/71313 | E34: Mavleod | F34: 2023 | G34: =39.7+(144.4) -> 184.1 | I34: =F34-G34-H34 -> 1838.9 | J34: Card | K34: 1 | L34: 1 | M34: 0 | N34: 1 | O34: 1 | P34: 1 | Q34: 1 | R34: 1 | S34: 1 | U34: 09/07 CB - Attended by Daniel B | V34: =226+1999.3 -> 2225.3
B35: =B34+1 -> 6 | C35: 45834 | D35: 71018 | E35: Preston | F35: 1053 | G35: 39.7 | I35: =F35-G35-H35 -> 1013.3 | J35: Card | K35: 1 | L35: 1 | M35: 1 | N35: 1 | O35: 1 | P35: 1 | Q35: 1 | R35: 1 | S35: 1 | T35: 1 | V35: =119+1039.3 -> 1158.3
B36: =B35+1 -> 7 | C36: 45835 | D36: 71065 | E36: Elsternwick | F36: 681 | I36: =F36-G36-H36 -> 681 | J36: Card | K36: 1 | L36: 1 | M36: 1 | N36: 1 | O36: 1 | P36: 1 | Q36: 1 | R36: 1 | S36: 1 | U36: 27 Jun - Paying 1hr O/T | V36: =75+674.1 -> 749.1
B37: =B36+1 -> 8 | C37: 45835 | D37: 71086/85951516 | E37: Richmond | F37: 1138 | G37: 39.7 | I37: =F37-G37-H37 -> 1098.3 | J37: Card | K37: 1 | L37: 0 | M37: 1 | N37: 1 | O37: 1 | P37: 1 | Q37: 1 | R37: 1 | S37: 1 | U37: 27 Jun - Paying 1.25hrs O/T | V37: 1251.8
F38: =SUM(F30:F37) -> 19726 | G38: =SUM(G30:G37) -> 5193.7 | H38: =SUM(H30:H37) -> 0 | I38: =SUM(I30:I37) -> 14532.3 | K38: =COUNT(K30:K37) -> 8 | L38: =COUNT(L30:L37) -> 8 | M38: =COUNT(M30:M37) -> 8 | N38: =COUNT(N30:N37) -> 8 | O38: =COUNT(O30:O37) -> 8 | P38: =COUNT(P30:P37) -> 8 | Q38: =COUNT(Q30:Q37) -> 8 | R38: =COUNT(R30:R37) -> 8 | S38: =COUNT(S30:S37) -> 8
K39: =SUM(K30:K37) -> 8 | L39: =SUM(L30:L37) -> 7 | M39: =SUM(M30:M37) -> 7 | N39: =SUM(N30:N37) -> 8 | O39: =SUM(O30:O37) -> 8 | P39: =SUM(P30:P37) -> 5 | Q39: =SUM(Q30:Q37) -> 8 | R39: =SUM(R30:R37) -> 7 | S39: =SUM(S30:S37) -> 6
B41: CURRENT JOBS COMPLETED (AWAITING PAYMENT)
A42: 26/06 CB26/06 | B42: 1 | C42: 45831 | D42: 70938/85882653 | E42: Reservoir | F42: 5133 | G42: =39.7+(1906.7+43.85)+250+200 -> 2440.25 | I42: =F42-G42-H42 -> 2692.75 | J42: Card | K42: 1 | L42: 1 | M42: 0 | N42: 1 | O42: 1 | P42: 0 | Q42: 1 | R42: 0 | S42: 1 | U42: 26/06 CB - Attended by Matthew H ISSUE - No water pressure ; 24/06 - WIP&Completed by Tolga; 23/06 - WIP By Tolga , Ben | V42: =565+2500 -> 3065
B43: =B42+1 -> 2 | C43: 45832 | D43: 70976/85898894 | E43: Carlton | F43: =681-681 -> 0 | I43: =F43-G43-H43 -> 0 | K43: 1 | L43: 1 | N43: 1 | O43: 1 | P43: 0 | Q43: 0 | R43: 0 | S43: 0 | U43: Payment update not Available in invoice Tab
B44: =B43+1 -> 3 | C44: 45832 | D44: 70976/85899215 | E44: Carlton | F44: 2794 | G44: =39.7+(46.62+153.12+243.81)+200 -> 683.25 | I44: =F44-G44-H44 -> 2110.75 | J44: Card | K44: 1 | L44: 1 | M44: 1 | N44: 1 | O44: 1 | P44: 0 | Q44: 1 | R44: 1 | S44: 0 | T44: 1 | U44: 24 Jun - Deduct 30mins O/T; 30/06 - WIP&Completed by Tolga ; 25/06 - WIP by Tolga Temp check by monday | V44: =75+674.01+307.5+255.5 -> 1312.01
B45: =B44+1 -> 4 | C45: 45833 | D45: 70918/85908669 | E45: Doncaster | F45: 681 | I45: =F45-G45-H45 -> 681 | K45: 1 | L45: 1 | N45: 1 | O45: 1 | P45: 1 | Q45: 1 | R45: 1 | S45: 1 | U45: 26/06 - WIP&Completed by Alex ; 25/06 - WIP& Completed by Jarrod , Ben , Alex; Payment update not Available in invoice Tab
...

Sheet Bradley
B3: WEEKLY COMMISSION | F3: WEEK ENDING | G3: 45893
K4: PHOTOS | N4: QUOTE | Q4: INVOICE
B5: BOOKED JOBS | C5: =C6+C7 -> 8 | E5: WEEKLY TARGET | K5: BEFORE | L5: AFTER | M5: RECEIPT | N5: DESCRIPTION | O5: SIGNED | P5: EMAILED | Q5: DESCRIPTION | R5: SIGNED | S5: EMAILED | T5: 5 Star Review
B6: SUCCESSFUL | C6: =P13 -> 2 | E6: Tier 1 | F6: 0.05 | J6: TAKEN | K6: =K32 -> 1 | L6: =L32 -> 0 | M6: =M32 -> 1 | N6: =N32 -> 1 | O6: =O32 -> 1 | P6: =P32 -> 1 | Q6: =Q32 -> 1 | R6: =R32 -> 1 | S6: =S32 -> 0 | T6: =T46 -> 0
B7: UNSUCCESSFUL | C7: =P14 -> 6 | J7: % | K7: =K32/K31 -> 1 | L7: =L32/L31 -> 0 | M7: =M32/M31 -> 1 | N7: =N32/N31 -> 1 | O7: =O32/O31 -> 1 | P7: =P32/P31 -> 1 | Q7: =Q32/Q31 -> 1 | R7: =R32/R31 -> 1 | S7: =S32/S31 -> 0 | U7: M8 Notes
B8: SUCESSFUL (%) | C8: =P15 -> 0.25
F9: ACTUAL | G9: POTENTIAL | H9: Exc. SUPER
B10: AVERAGE SALE | C10: =P16 -> 1775.585 | E10: NET PROFIT | F10: =P12 -> 3551.17 | G10: =I31+I36 -> 3551.17 | H10: 27 Aug - 5% will be paid out upon Achieving 5 Star Reviews | K10: DAILY NET PROFIT | R10: WEEKDAY | S10: WEEKEND
E11: UNLOCKED | F11: =F6 -> 0.05 | K11: MON | L11: TUE | M11: WED | N11: THU | O11: FRI | P11: Total | Q11: SAT | R11: Awaiting Payment | S11: Awaiting Payment
E12: COMMISSION - PAY OUT | F12: =(F10-I30-I35)*F11 -> 0 | G12: $- | H12: =F12/1.12 -> 0 | L12: 0 | M12: 0 | N12: =I30+I35 -> 3551.17 | P12: =SUM(K12:O12) -> 3551.17 | Q12: 0 | R12: =I36 -> 2870.17 | S12: 0
E13: EMERGENCY | F13: =Q12 -> 0 | G13: $- | J13: Successful | L13: 0 | M13: 0 | N13: 2 | O13: 0 | P13: =SUM(K13:O13) -> 2
E14: EMERGENCY - PAY OUT | F14: =F13*0.25 -> 0 | G14: $- | H14: =F14/1.12 -> 0 | J14: Unsuccessful | L14: 1 | M14: 3 | N14: 0 | O14: 2 | P14: =SUM(K14:O14) -> 6
E15: PREV. WEEK | G15: $- | J15: Success rate | K15: =K13/(K13+K14) -> #DIV/0! | L15: =L13/(L13+L14) -> 0 | M15: =M13/(M13+M14) -> 0 | N15: =N13/(N13+N14) -> 1 | O15: =O13/(O13+O14) -> 0 | P15: =P13/(P13+P14) -> 0.25 | Q15: =Q13/(Q13+Q14) -> #DIV/0!
E16: PREV. WEEK - PAY OUT | F16: =F15*0.05 -> 0 | G16: $- | H16: =F16/1.12 -> 0 | J16: Avg sale | K16: =K12/K13 -> #DIV/0! | L16: =L12/L13 -> #DIV/0! | M16: =M12/M13 -> #DIV/0! | N16: =N12/N13 -> 1775.585 | O16: =O12/O13 -> #DIV/0! | P16: =P12/P13 -> 1775.585 | Q16: =Q12/Q13 -> #DIV/0!
E17: 5 Star Review | H17: =F17/1.12 -> 0
E18: 5 Star Notes | F18: =T7 -> 0 | K18: Managment Summary - SALES ONLY - COLUMN F | R18: WEEKDAY | S18: WEEKEND
K19: MON | L19: TUE | M19: WED | N19: THU | O19: FRI | P19: Total | Q19: SAT | R19: Awaiting Payment | S19: Awaiting Payment
L20: 0 | M20: 0 | N20: =F30+F35 -> 4793 | P20: =SUM(K20:O20) -> 4793 | Q20: 0 | R20: =F35 -> 4112 | S20: 0
J21: Successful | K21: =K13 -> 0 | L21: =L13 -> 0 | M21: =M13 -> 0 | N21: =N13 -> 2 | O21: =O13 -> 0 | P21: =P13 -> 2 | Q21: =Q13 -> 0
J22: Unsuccessful | K22: =K14 -> 0 | L22: =L14 -> 1 | M22: =M14 -> 3 | N22: =N14 -> 0 | O22: =O14 -> 2 | P22: =P14 -> 6 | Q22: =Q14 -> 0
J23: Success rate | K23: =K21/(K21+K22) -> #DIV/0! | L23: =L21/(L21+L22) -> 0 | M23: =M21/(M21+M22) -> 0 | N23: =N21/(N21+N22) -> 1 | O23: =O21/(O21+O22) -> 0 | P23: =P21/(P21+P22) -> 0.25 | Q23: =Q21/(Q21+Q22) -> #DIV/0!
J24: Avg sale | K24: =K20/K21 -> #DIV/0! | L24: =L20/L21 -> #DIV/0! | M24: =M20/M21 -> #DIV/0! | N24: =N20/N21 -> 2396.5 | O24: =O20/O21 -> #DIV/0! | P24: =P20/P21 -> 2396.5 | Q24: =Q20/Q21 -> #DIV/0!
B27: JOB DETAILS | F27: JOB AMOUNT | K27: PHOTOS | N27: QUOTE | Q27: INVOICE | U27: NOTES
B28: JOB STATUS | C28: DATE | D28: JOB # | E28: SUBURB | F28: AMOUNT EXC. GST | G28: MATERIALS | H28: Merchant Fees | I28: NET PROFIT | J28: PAID | K28: BEFORE | L28: AFTER | M28: RECEIPT | N28: DESCRIPTION | O28: SIGNED | P28: EMAILED | Q28: DESCRIPTION | R28: SIGNED | S28: EMAILED | T28: 5 Star Review | V28: EFTPOS | W28: CASH | X28: Payment Plan
B29: COMPLETED & PAID JOBS
B30: 1 | C30: 45890 | D30: 72507 | E30: Keilor East | F30: 681 | I30: =F30-G30-H30 -> 681 | J30: Card | K30: 1 | L30: 0 | M30: 1 | N30: 1 | O30: 1 | P30: 1 | Q30: 1 | R30: 1 | S30: 0 | U30: 21 Aug - 1hr O/T More Than Comm'ns | V30: 749.1
F31: =SUM(F30) -> 681 | G31: =SUM(G30) -> 0 | H31: =SUM(H30) -> 0 | I31: =SUM(I30) -> 681 | K31: =COUNT(K30:K30) -> 1 | L31: =COUNT(L30:L30) -> 1 | M31: =COUNT(M30:M30) -> 1 | N31: =COUNT(N30:N30) -> 1 | O31: =COUNT(O30:O30) -> 1 | P31: =COUNT(P30:P30) -> 1 | Q31: =COUNT(Q30:Q30) -> 1 | R31: =COUNT(R30:R30) -> 1 | S31: =COUNT(S30:S30) -> 1
K32: =SUM(K30:K30) -> 1 | L32: =SUM(L30:L30) -> 0 | M32: =SUM(M30:M30) -> 1 | N32: =SUM(N30:N30) -> 1 | O32: =SUM(O30:O30) -> 1 | P32: =SUM(P30:P30) -> 1 | Q32: =SUM(Q30:Q30) -> 1 | R32: =SUM(R30:R30) -> 1 | S32: =SUM(S30:S30) -> 0
B34: CURRENT JOBS COMPLETED (AWAITING PAYMENT)
B35: 1 | C35: 45890 | D35: 72546/72507 | E35: Keilor East | F35: 4112 | G35: =39.7+(847.9+27.43+26.8)+300 -> 1241.83 | I35: =F35-G35-H35 -> 2870.17 | J35: Card/EFT | K35: 1 | L35: 0 | M35: 1 | N35: 1 | O35: 1 | P35: 1 | Q35: 1 | R35: 1 | S35: 0 | U35: 21 Aug - Deduct 1hr O/T; 22/8-WIP by Matthew | V35: =450+3000 -> 3450
F36: =SUM(F35) -> 4112 | G36: =SUM(G35) -> 1241.83 | H36: =SUM(H35) -> 0 | I36: =SUM(I35) -> 2870.17
B38: UNSUCCESSFUL JOBS
B39: 1 | C39: 45888 | D39: 72430 | E39: Avondale Heights | F39: 775 | G39: 39.7 | I39: =F39-G39-H39 -> 735.3 | J39: N/A | K39: 1 | N39: 1 | Q39: 1 | R39: 1 | S39: 1
B40: =B39+1 -> 2 | C40: 45889 | D40: 72438 | E40: Cairnlea | F40: 8641 | G40: 39.7 | I40: =F40-G40-H40 -> 8601.3 | J40: N/A | K40: 1 | N40: 1 | Q40: 1 | R40: 1 | S40: 1
B41: =B40+1 -> 3 | C41: 45889 | D41: 72451 | E41: Saint Albans | F41: 7753 | G41: 39.7 | I41: =F41-G41-H41 -> 7713.3 | J41: N/A | K41: 1 | N41: 1 | Q41: 1 | R41: 1 | S41: 1
B42: =B41+1 -> 4 | C42: 45889 | D42: 72437 | E42: Truganina | F42: 7753 | G42: 39.7 | I42: =F42-G42-H42 -> 7713.3 | J42: N/A | K42: 1 | N42: 1 | Q42: 1 | R42: 1 | S42: 1
B43: =B42+1 -> 5 | C43: 45891 | D43: 72538 | E43: Point Cook | F43: 1053 | G43: 39.7 | I43: =F43-G43-H43 -> 1013.3 | J43: N/A | K43: 1 | N43: 1 | Q43: 1 | R43: 1 | S43: 1
B44: =B43+1 -> 6 | C44: 45891 | D44: 72548 | E44: Burwood | F44: 0 | I44: =F44-G44-H44 -> 0 | J44: Quote | U44: 22/08 - As per Bradley's note - "Job was a call back, other toilet is fine." - No initial jobs were found for this same customer
F45: =SUM(F39:F44) -> 25975 | G45: =SUM(G39:G44) -> 198.5 | H45: =SUM(H39:H44) -> 0 | I45: =SUM(I39:I44) -> 25776.5
T46: =SUM(T30:T45) -> 0 | V46: =SUM(V30:V45) -> 4199.1 | W46: =SUM(W30:W45) -> 0 | X46: =SUM(X30:X45) -> 0
...

Sheet Daniel B
B3: WEEKLY COMMISSION | F3: WEEK ENDING | G3: 45970
K4: PHOTOS | N4: QUOTE | Q4: INVOICE
B5: BOOKED JOBS | C5: =C6+C7 -> 0 | E5: WEEKLY TARGET | K5: BEFORE | L5: AFTER | M5: RECEIPT | N5: DESCRIPTION | O5: SIGNED | P5: EMAILED | Q5: DESCRIPTION | R5: SIGNED | S5: EMAILED | T5: 5 Star Review
B6: SUCCESSFUL | C6: =P13 -> 0 | E6: Tier 1 | F6: 0.05 | J6: TAKEN | K6: =K32 -> 0 | L6: =L32 -> 0 | M6: =M32 -> 0 | N6: =N32 -> 0 | O6: =O32 -> 0 | P6: =P32 -> 0 | Q6: =Q32 -> 0 | R6: =R32 -> 0 | S6: =S32 -> 0 | T6: =T33 -> 0
B7: UNSUCCESSFUL | C7: =P14 -> 0 | J7: % | K7: =K32/K31 -> #DIV/0! | L7: =L32/L31 -> #DIV/0! | M7: =M32/M31 -> #DIV/0! | N7: =N32/N31 -> #DIV/0! | O7: =O32/O31 -> #DIV/0! | P7: =P32/P31 -> #DIV/0! | Q7: =Q32/Q31 -> #DIV/0! | R7: =R32/R31 -> #DIV/0! | S7: =S32/S31 -> #DIV/0! | U7: M8 Notes
B8: SUCESSFUL (%) | C8: =P15 -> #DIV/0!
F9: ACTUAL | G9: POTENTIAL | H9: Exc. SUPER
B10: AVERAGE SALE | C10: =P16 -> #DIV/0! | E10: NET PROFIT | F10: =P12 -> 0 | G10: =I31 -> 0 | K10: DAILY NET PROFIT | R10: WEEKDAY | S10: WEEKEND
E11: UNLOCKED | F11: =F6 -> 0.05 | K11: MON | L11: TUE | M11: WED | N11: THU | O11: FRI | P11: Total | Q11: SAT | R11: Awaiting Payment | S11: Awaiting Payment
E12: COMMISSION - PAY OUT | F12: =F10*F11 -> 0 | G12: $- | H12: =F12/1.12 -> 0 | P12: =SUM(K12:O12) -> 0 | Q12: 0 | R12: 0 | S12: 0
E13: EMERGENCY | F13: =Q12 -> 0 | G13: $- | J13: Successful | P13: =SUM(K13:O13) -> 0
E14: EMERGENCY - PAY OUT | F14: =F13*0.25 -> 0 | G14: $- | H14: =F14/1.12 -> 0 | J14: Unsuccessful | P14: =SUM(K14:O14) -> 0
E15: PREV. WEEK | G15: $- | J15: Success rate | K15: =K13/(K13+K14) -> #DIV/0! | L15: =L13/(L13+L14) -> #DIV/0! | M15: =M13/(M13+M14) -> #DIV/0! | N15: =N13/(N13+N14) -> #DIV/0! | O15: =O13/(O13+O14) -> #DIV/0! | P15: =P13/(P13+P14) -> #DIV/0! | Q15: =Q13/(Q13+Q14) -> #DIV/0!
E16: PREV. WEEK - PAY OUT | F16: =F15*0.05 -> 0 | G16: $- | H16: =F16/1.12 -> 0 | J16: Avg sale | K16: =K12/K13 -> #DIV/0! | L16: =L12/L13 -> #DIV/0! | M16: =M12/M13 -> #DIV/0! | N16: =N12/N13 -> #DIV/0! | O16: =O12/O13 -> #DIV/0! | P16: =P12/P13 -> #DIV/0! | Q16: =Q12/Q13 -> #DIV/0!
E17: 5 Star Review | H17: =F17/1.12 -> 0
E18: 5 Star Notes | F18: =T7 -> 0 | K18: Managment Summary - SALES ONLY - COLUMN F | R18: WEEKDAY | S18: WEEKEND
K19: MON | L19: TUE | M19: WED | N19: THU | O19: FRI | P19: Total | Q19: SAT | R19: Awaiting Payment | S19: Awaiting Payment
P20: =SUM(K20:O20) -> 0 | Q20: 0 | R20: 0 | S20: 0
J21: Successful | K21: =K13 -> 0 | L21: =L13 -> 0 | M21: =M13 -> 0 | N21: =N13 -> 0 | O21: =O13 -> 0 | P21: =P13 -> 0 | Q21: =Q13 -> 0
J22: Unsuccessful | K22: =K14 -> 0 | L22: =L14 -> 0 | M22: =M14 -> 0 | N22: =N14 -> 0 | O22: =O14 -> 0 | P22: =P14 -> 0 | Q22: =Q14 -> 0
J23: Success rate | K23: =K21/(K21+K22) -> #DIV/0! | L23: =L21/(L21+L22) -> #DIV/0! | M23: =M21/(M21+M22) -> #DIV/0! | N23: =N21/(N21+N22) -> #DIV/0! | O23: =O21/(O21+O22) -> #DIV/0! | P23: =P21/(P21+P22) -> #DIV/0! | Q23: =Q21/(Q21+Q22) -> #DIV/0!
J24: Avg sale | K24: =K20/K21 -> #DIV/0! | L24: =L20/L21 -> #DIV/0! | M24: =M20/M21 -> #DIV/0! | N24: =N20/N21 -> #DIV/0! | O24: =O20/O21 -> #DIV/0! | P24: =P20/P21 -> #DIV/0! | Q24: =Q20/Q21 -> #DIV/0!
B27: JOB DETAILS | F27: JOB AMOUNT | K27: PHOTOS | N27: QUOTE | Q27: INVOICE | U27: NOTES
B28: JOB STATUS | C28: DATE | D28: JOB # | E28: SUBURB | F28: AMOUNT EXC. GST | G28: MATERIALS | H28: Merchant Fees | I28: NET PROFIT | J28: PAID | K28: BEFORE | L28: AFTER | M28: RECEIPT | N28: DESCRIPTION | O28: SIGNED | P28: EMAILED | Q28: DESCRIPTION | R28: SIGNED | S28: EMAILED | T28: 5 Star Review | V28: EFTPOS | W28: CASH | X28: Payment Plan
B29: COMPLETED & PAID JOBS
B30: 1 | I30: =F30-G30-H30 -> 0
F31: =SUM(F30:F30) -> 0 | G31: =SUM(G30:G30) -> 0 | H31: =SUM(H30:H30) -> 0 | I31: =SUM(I30:I30) -> 0 | K31: =COUNT(K30:K30) -> 0 | L31: =COUNT(L30:L30) -> 0 | M31: =COUNT(M30:M30) -> 0 | N31: =COUNT(N30:N30) -> 0 | O31: =COUNT(O30:O30) -> 0 | P31: =COUNT(P30:P30) -> 0 | Q31: =COUNT(Q30:Q30) -> 0 | R31: =COUNT(R30:R30) -> 0 | S31: =COUNT(S30:S30) -> 0
K32: =SUM(K30:K30) -> 0 | L32: =SUM(L30:L30) -> 0 | M32: =SUM(M30:M30) -> 0 | N32: =SUM(N30:N30) -> 0 | O32: =SUM(O30:O30) -> 0 | P32: =SUM(P30:P30) -> 0 | Q32: =SUM(Q30:Q30) -> 0 | R32: =SUM(R30:R30) -> 0 | S32: =SUM(S30:S30) -> 0
T33: =SUM(T30:T32) -> 0 | V33: =SUM(V30:V32) -> 0 | W33: =SUM(W30:W32) -> 0 | X33: =SUM(X30:X32) -> 0

Sheet Elliot
B2: WEEKLY COMMISSION | F2: WEEK ENDING | G2: 45858
K3: PHOTOS | N3: QUOTE | Q3: INVOICE
B4: BOOKED JOBS | C4: =C5+C6 -> 1 | E4: WEEKLY TARGET | K4: BEFORE | L4: AFTER | M4: RECEIPT | N4: DESCRIPTION | O4: SIGNED | P4: EMAILED | Q4: DESCRIPTION | R4: SIGNED | S4: EMAILED | T4: 5 Star Review
B5: SUCCESSFUL | C5: =P12 -> 1 | E5: Tier 1 | F5: 0.05 | J5: TAKEN | K5: =K31 -> 1 | L5: =L31 -> 1 | M5: =M31 -> 1 | N5: =N31 -> 1 | O5: =O31 -> 1 | P5: =P31 -> 1 | Q5: =Q31 -> 1 | R5: =R31 -> 1 | S5: =S31 -> 1 | T5: =T32 -> 1 | U5: 1X Heath
B6: UNSUCCESSFUL | C6: =P13 -> 0 | J6: % | K6: =K31/K30 -> 1 | L6: =L31/L30 -> 1 | M6: =M31/M30 -> 1 | N6: =N31/N30 -> 1 | O6: =O31/O30 -> 1 | P6: =P31/P30 -> 1 | Q6: =Q31/Q30 -> 1 | R6: =R31/R30 -> 1 | S6: =S31/S30 -> 1 | U6: M8 Notes
B7: SUCESSFUL (%) | C7: =P14 -> 1
F8: ACTUAL | G8: POTENTIAL | H8: Exc. SUPER
B9: AVERAGE SALE | C9: =P15 -> 1221.3 | E9: NET PROFIT | F9: =P11 -> 1221.3 | G9: =I30 -> 1221.3 | K9: DAILY NET PROFIT | R9: WEEKDAY | S9: WEEKEND
E10: UNLOCKED | F10: =F5 -> 0.05 | K10: MON | L10: TUE | M10: WED | N10: THU | O10: FRI | P10: Total | Q10: SAT | R10: Awaiting Payment | S10: Awaiting Payment
E11: COMMISSION - PAY OUT | F11: =F9*F10 -> 61.065 | G11: $- | H11: =F11/1.12 -> 54.522321 | N11: =I29 -> 1221.3 | P11: =SUM(K11:O11) -> 1221.3 | Q11: 0 | R11: =0 -> 0 | S11: 0
E12: EMERGENCY | F12: =Q11 -> 0 | G12: $- | J12: Successful | N12: 1 | P12: =SUM(K12:O12) -> 1
E13: EMERGENCY - PAY OUT | F13: =F12*0.25 -> 0 | G13: $- | H13: =F13/1.12 -> 0 | J13: Unsuccessful | N13: 0 | P13: =SUM(K13:O13) -> 0
E14: PREV. WEEK | G14: $- | J14: Success rate | K14: =K12/(K12+K13) -> #DIV/0! | L14: =L12/(L12+L13) -> #DIV/0! | M14: =M12/(M12+M13) -> #DIV/0! | N14: =N12/(N12+N13) -> 1 | O14: =O12/(O12+O13) -> #DIV/0! | P14: =P12/(P12+P13) -> 1 | Q14: =Q12/(Q12+Q13) -> #DIV/0!
E15: PREV. WEEK - PAY OUT | F15: =F14*0.05 -> 0 | G15: $- | H15: =F15/1.12 -> 0 | J15: Avg sale | K15: =K11/K12 -> #DIV/0! | L15: =L11/L12 -> #DIV/0! | M15: =M11/M12 -> #DIV/0! | N15: =N11/N12 -> 1221.3 | O15: =O11/O12 -> #DIV/0! | P15: =P11/P12 -> 1221.3 | Q15: =Q11/Q12 -> #DIV/0!
E16: 5 Star Review | H16: =F16/1.12 -> 0
E17: 5 Star Notes | F17: =T6 -> 0 | K17: Managment Summary - SALES ONLY - COLUMN F | R17: WEEKDAY | S17: WEEKEND
K18: MON | L18: TUE | M18: WED | N18: THU | O18: FRI | P18: Total | Q18: SAT | R18: Awaiting Payment | S18: Awaiting Payment
N19: =F29 -> 1461 | O19: =Heath!F127 -> 481 | P19: =SUM(K19:O19) -> 1942 | Q19: 0 | R19: =0 -> 0 | S19: 0
J20: Successful | K20: =K12 -> 0 | L20: =L12 -> 0 | M20: =M12 -> 0 | N20: =N12 -> 1 | O20: =O12 -> 0 | P20: =P12 -> 1 | Q20: =Q12 -> 0
J21: Unsuccessful | K21: =K13 -> 0 | L21: =L13 -> 0 | M21: =M13 -> 0 | N21: =N13 -> 0 | O21: =O13 -> 0 | P21: =P13 -> 0 | Q21: =Q13 -> 0
J22: Success rate | K22: =K20/(K20+K21) -> #DIV/0! | L22: =L20/(L20+L21) -> #DIV/0! | M22: =M20/(M20+M21) -> #DIV/0! | N22: =N20/(N20+N21) -> 1 | O22: =O20/(O20+O21) -> #DIV/0! | P22: =P20/(P20+P21) -> 1 | Q22: =Q20/(Q20+Q21) -> #DIV/0!
J23: Avg sale | K23: =K19/K20 -> #DIV/0! | L23: =L19/L20 -> #DIV/0! | M23: =M19/M20 -> #DIV/0! | N23: =N19/N20 -> 1461 | O23: =O19/O20 -> #DIV/0! | P23: =P19/P20 -> 1942 | Q23: =Q19/Q20 -> #DIV/0!
B26: JOB DETAILS | F26: JOB AMOUNT | K26: PHOTOS | N26: QUOTE | Q26: INVOICE | U26: NOTES
B27: JOB STATUS | C27: DATE | D27: JOB # | E27: SUBURB | F27: AMOUNT EXC. GST | G27: MATERIALS | H27: Merchant Fees | I27: NET PROFIT | J27: PAID | K27: BEFORE | L27: AFTER | M27: RECEIPT | N27: DESCRIPTION | O27: SIGNED | P27: EMAILED | Q27: DESCRIPTION | R27: SIGNED | S27: EMAILED | T27: 5 Star Review | V27: EFTPOS | W27: CASH | X27: Payment Plan
B28: COMPLETED & PAID JOBS
B29: 1 | C29: 45855 | D29: 71475 | E29: Elwood | F29: 1461 | G29: =39.7+200 -> 239.7 | I29: =F29-G29-H29 -> 1221.3 | J29: Card | K29: 1 | L29: 1 | M29: 1 | N29: 1 | O29: 1 | P29: 1 | Q29: 1 | R29: 1 | S29: 1 | T29: 1 | U29: 17/07-WIP & Completed by Elliot, Heath | V29: =160.71+1446.39 -> 1607.1
F30: =SUM(F29) -> 1461 | G30: =SUM(G29) -> 239.7 | H30: =SUM(H29) -> 0 | I30: =SUM(I29) -> 1221.3 | K30: =COUNT(K29:K29) -> 1 | L30: =COUNT(L29:L29) -> 1 | M30: =COUNT(M29:M29) -> 1 | N30: =COUNT(N29:N29) -> 1 | O30: =COUNT(O29:O29) -> 1 | P30: =COUNT(P29:P29) -> 1 | Q30: =COUNT(Q29:Q29) -> 1 | R30: =COUNT(R29:R29) -> 1 | S30: =COUNT(S29:S29) -> 1
K31: =SUM(K29:K29) -> 1 | L31: =SUM(L29:L29) -> 1 | M31: =SUM(M29:M29) -> 1 | N31: =SUM(N29:N29) -> 1 | O31: =SUM(O29:O29) -> 1 | P31: =SUM(P29:P29) -> 1 | Q31: =SUM(Q29:Q29) -> 1 | R31: =SUM(R29:R29) -> 1 | S31: =SUM(S29:S29) -> 1
T32: =SUM(T29:T31) -> 1 | V32: =SUM(V29:V31) -> 1607.1 | W32: =SUM(W29:W31) -> 0 | X32: =SUM(X29:X31) -> 0
B35: WEEKLY COMMISSION | F35: WEEK ENDING | G35: 45865
K36: PHOTOS | N36: QUOTE | Q36: INVOICE
B37: BOOKED JOBS | C37: =C38+C39 -> 1 | E37: WEEKLY TARGET | K37: BEFORE | L37: AFTER | M37: RECEIPT | N37: DESCRIPTION | O37: SIGNED | P37: EMAILED | Q37: DESCRIPTION | R37: SIGNED | S37: EMAILED | T37: 5 Star Review
B38: SUCCESSFUL | C38: =P45 -> 1 | E38: Tier 1 | F38: 0.05 | J38: TAKEN | K38: =K64 -> 1 | L38: =L64 -> 1 | M38: =M64 -> 1 | N38: =N64 -> 1 | O38: =O64 -> 1 | P38: =P64 -> 1 | Q38: =Q64 -> 1 | R38: =R64 -> 1 | S38: =S64 -> 1 | T38: =T82 -> 0
B39: UNSUCCESSFUL | C39: =P46 -> 0 | J39: % | K39: =K64/K63 -> 1 | L39: =L64/L63 -> 1 | M39: =M64/M63 -> 1 | N39: =N64/N63 -> 1 | O39: =O64/O63 -> 1 | P39: =P64/P63 -> 1 | Q39: =Q64/Q63 -> 1 | R39: =R64/R63 -> 1 | S39: =S64/S63 -> 1 | U39: M8 Notes
B40: SUCESSFUL (%) | C40: =P47 -> 1
F41: ACTUAL | G41: POTENTIAL | H41: Exc. SUPER
B42: AVERAGE SALE | C42: =P48 -> 774.3 | E42: NET PROFIT | F42: =P44 -> 774.3 | G42: =I63 -> 774.3 | K42: DAILY NET PROFIT | R42: WEEKDAY | S42: WEEKEND
E43: UNLOCKED | F43: =F38 -> 0.05 | K43: MON | L43: TUE | M43: WED | N43: THU | O43: FRI | P43: Total | Q43: SAT | R43: Awaiting Payment | S43: Awaiting Payment
E44: COMMISSION - PAY OUT | F44: =F42*F43 -> 38.715 | G44: $- | H44: =F44/1.12 -> 34.566964 | K44: =I62 -> 774.3 | L44: 0 | M44: 0 | N44: 0 | O44: 0 | P44: =SUM(K44:O44) -> 774.3 | Q44: =I67+I68+I69+I70 -> 3599.6 | R44: 0 | S44: =0 -> 0
E45: EMERGENCY | F45: =Q44 -> 3599.6 | G45: $- | I45: O/T=10.75hrs | J45: Successful | K45: 1 | L45: 0 | M45: 0 | N45: 0 | O45: 0 | P45: =SUM(K45:O45) -> 1 | Q45: 4
...

Sheet Eric - No OT
B2: WEEKLY COMMISSION | F2: WEEK ENDING | G2: 45970
K3: PHOTOS | N3: QUOTE | Q3: INVOICE
B4: BOOKED JOBS | C4: =C5+C6 -> 0 | E4: WEEKLY TARGET | K4: BEFORE | L4: AFTER | M4: RECEIPT | N4: DESCRIPTION | O4: SIGNED | P4: EMAILED | Q4: DESCRIPTION | R4: SIGNED | S4: EMAILED | T4: 5 Star Review
B5: SUCCESSFUL | C5: =P12 -> 0 | E5: Tier 1 | F5: <$25000 | G5: 0.05 | J5: TAKEN | K5: =K47 -> 0 | L5: =L47 -> 0 | M5: =M47 -> 0 | N5: =N47 -> 0 | O5: =O47 -> 0 | P5: =P47 -> 0 | Q5: =Q47 -> 0 | R5: =R47 -> 0 | S5: =S47 -> 0 | T5: =T144 -> 0
B6: UNSUCCESSFUL | C6: =P13 -> 0 | E6: Tier 2 | F6: >= $25000 | G6: 0.1 | J6: % | K6: =K47/K46 -> #DIV/0! | L6: =L47/L46 -> #DIV/0! | M6: =M47/M46 -> #DIV/0! | N6: =N47/N46 -> #DIV/0! | O6: =O47/O46 -> #DIV/0! | P6: =P47/P46 -> #DIV/0! | Q6: =Q47/Q46 -> #DIV/0! | R6: =R47/R46 -> #DIV/0! | S6: =S47/S46 -> #DIV/0! | U6: M8 Notes
B7: SUCESSFUL (%) | C7: =P14 -> #DIV/0!
F8: ACTUAL | G8: POTENTIAL | H8: Exc. SUPER
B9: AVERAGE SALE | C9: =P15 -> #DIV/0! | E9: NET PROFIT | F9: =P11 -> 0 | G9: =I46+I80+I102 -> 0 | K9: DAILY NET PROFIT | R9: WEEKDAY | S9: WEEKEND
E10: UNLOCKED | F10: =IF(F9>=25000,10%,5%) -> 0.05 | K10: MON | L10: TUE | M10: WED | N10: THU | O10: FRI | P10: Total | Q10: SAT | R10: Awaiting Payment | S10: Awaiting Payment
E11: COMMISSION - PAY OUT | F11: =F9*F10 -> 0 | G11: $- | H11: =F11/1.12 -> 0 | P11: =SUM(K11:O11) -> 0 | Q11: 0 | R11: =I80+I102 -> 0 | S11: =+I91+I113 -> 0
E12: EMERGENCY | F12: =Q11 -> 0 | G12: $- | J12: Successful | P12: =SUM(K12:O12) -> 0
E13: EMERGENCY - PAY OUT | F13: =F12*0.25 -> 0 | G13: $- | H13: =F13/1.12 -> 0 | J13: Unsuccessful | P13: =SUM(K13:O13) -> 0
E14: PREV. WEEK | F14: 0 | G14: $- | J14: Success rate | K14: =K12/(K12+K13) -> #DIV/0! | L14: =L12/(L12+L13) -> #DIV/0! | M14: =M12/(M12+M13) -> #DIV/0! | N14: =N12/(N12+N13) -> #DIV/0! | O14: =O12/(O12+O13) -> #DIV/0! | P14: =P12/(P12+P13) -> #DIV/0! | Q14: =Q12/(Q12+Q13) -> #DIV/0!
E15: PREV. WEEK - PAY OUT | F15: =F14*0.05 -> 0 | G15: $- | H15: =F15/1.12 -> 0 | J15: Avg sale | K15: =K11/K12 -> #DIV/0! | L15: =L11/L12 -> #DIV/0! | M15: =M11/M12 -> #DIV/0! | N15: =N11/N12 -> #DIV/0! | O15: =O11/O12 -> #DIV/0! | P15: =P11/P12 -> #DIV/0! | Q15: =Q11/Q12 -> #DIV/0!
E16: 5 Star Review | H16: =F16/1.12 -> 0
E17: 5 Star Notes | F17: =T6 -> 0 | K17: Managment Summary - SALES ONLY - COLUMN F | R17: WEEKDAY | S17: WEEKEND
K18: MON | L18: TUE | M18: WED | N18: THU | O18: FRI | P18: Total | Q18: SAT | R18: Awaiting Payment | S18: Awaiting Payment
P19: =SUM(K19:O19) -> 0 | Q19: 0 | R19: =F80+F102 -> 0 | S19: =F91+F113 -> 0
J20: Successful | K20: =K12 -> 0 | L20: =L12 -> 0 | M20: =M12 -> 0 | N20: =N12 -> 0 | O20: =O12 -> 0 | P20: =P12 -> 0 | Q20: =Q12 -> 0
J21: Unsuccessful | K21: =K13 -> 0 | L21: =L13 -> 0 | M21: =M13 -> 0 | N21: =N13 -> 0 | O21: =O13 -> 0 | P21: =P13 -> 0 | Q21: =Q13 -> 0
J22: Success rate | K22: =K20/(K20+K21) -> #DIV/0! | L22: =L20/(L20+L21) -> #DIV/0! | M22: =M20/(M20+M21) -> #DIV/0! | N22: =N20/(N20+N21) -> #DIV/0! | O22: =O20/(O20+O21) -> #DIV/0! | P22: =P20/(P20+P21) -> #DIV/0! | Q22: =Q20/(Q20+Q21) -> #DIV/0!
J23: Avg sale | K23: =K19/K20 -> #DIV/0! | L23: =L19/L20 -> #DIV/0! | M23: =M19/M20 -> #DIV/0! | N23: =N19/N20 -> #DIV/0! | O23: =O19/O20 -> #DIV/0! | P23: =P19/P20 -> #DIV/0! | Q23: =Q19/Q20 -> #DIV/0!
B27: JOB DETAILS | F27: JOB AMOUNT | K27: PHOTOS | N27: QUOTE | Q27: INVOICE | U27: NOTES
B28: JOB STATUS | C28: DATE | D28: JOB # | E28: SUBURB | F28: AMOUNT EXC. GST | G28: MATERIALS | H28: Merchant Fees | I28: NET PROFIT | J28: PAID | K28: BEFORE | L28: AFTER | M28: RECEIPT | N28: DESCRIPTION | O28: SIGNED | P28: EMAILED | Q28: DESCRIPTION | R28: SIGNED | S28: EMAILED | T28: 5 Star Review | V28: EFTPOS | W28: CASH | X28: Payment Plan
B29: COMPLETED & PAID JOBS
B30: 1 | I30: =F30-G30-H30 -> 0
B31: =B30+1 -> 2 | I31: =F31-G31-H31 -> 0
B32: =B31+1 -> 3 | I32: =F32-G32-H32 -> 0
B33: =B32+1 -> 4 | I33: =F33-G33-H33 -> 0
B34: =B33+1 -> 5 | I34: =F34-G34-H34 -> 0
B35: =B34+1 -> 6 | I35: =F35-G35-H35 -> 0
B36: =B35+1 -> 7 | I36: =F36-G36-H36 -> 0
B37: =B36+1 -> 8 | I37: =F37-G37-H37 -> 0
B38: =B37+1 -> 9 | I38: =F38-G38-H38 -> 0
B39: =B38+1 -> 10 | I39: =F39-G39-H39 -> 0
B40: =B39+1 -> 11 | I40: =F40-G40-H40 -> 0
B41: =B40+1 -> 12 | I41: =F41-G41-H41 -> 0
B42: =B41+1 -> 13 | I42: =F42-G42-H42 -> 0
... B45: =B44+1 -> 16 | I45: =F45-G45-H45 -> 0
F46: =SUM(F30:F45) -> 0 | G46: =SUM(G30:G45) -> 0 | H46: =SUM(H30:H45) -> 0 | I46: =SUM(I30:I45) -> 0 | K46: =COUNT(K30:K45) -> 0 | L46: =COUNT(L30:L45) -> 0 | M46: =COUNT(M30:M45) -> 0 | N46: =COUNT(N30:N45) -> 0 | O46: =COUNT(O30:O45) -> 0 | P46: =COUNT(P30:P45) -> 0 | Q46: =COUNT(Q30:Q45) -> 0 | R46: =COUNT(R30:R45) -> 0 | S46: =COUNT(S30:S45) -> 0
...

Sheet Jack M
B3: WEEKLY COMMISSION | F3: WEEK ENDING | G3: 45837
K4: PHOTOS | N4: QUOTE | Q4: INVOICE
